[2024-07-28 17:30:30|296|INFO|base_model.py:91]  session [1972747750704] and [RegressPredict] has an operator: QUERY.
[2024-07-28 17:30:31|296|INFO|sales_view.py:31]  Regress Predict init successfully
[2024-07-28 17:30:36|24916|ERROR|__init__.py:110]  send_from_directory error, info is 404 Not Found: The requested URL was not found on the server. If you entered the URL manually please check your spelling and try again.
[2024-07-28 17:30:36|24916|ERROR|__init__.py:111]  Traceback (most recent call last):
  File "D:\ruanjian\Python\Python310\lib\site-packages\flask\app.py", line 870, in full_dispatch_request
    rv = self.dispatch_request()
  File "D:\ruanjian\Python\Python310\lib\site-packages\flask\app.py", line 855, in dispatch_request
    return self.ensure_sync(self.view_functions[rule.endpoint])(**view_args)  # type: ignore[no-any-return]
  File "D:\ruanjian\Python\Python310\lib\site-packages\flask\app.py", line 260, in <lambda>
    view_func=lambda **kw: self_ref().send_static_file(**kw),  # type: ignore # noqa: B950
  File "D:\ruanjian\Python\Python310\lib\site-packages\flask\app.py", line 308, in send_static_file
    return send_from_directory(
  File "D:\ruanjian\Python\Python310\lib\site-packages\flask\helpers.py", line 552, in send_from_directory
    return werkzeug.utils.send_from_directory(  # type: ignore[return-value]
  File "D:\ruanjian\Python\Python310\lib\site-packages\werkzeug\utils.py", line 574, in send_from_directory
    raise NotFound()
werkzeug.exceptions.NotFound: 404 Not Found: The requested URL was not found on the server. If you entered the URL manually please check your spelling and try again.

